Workbook

Sheet Datos Históricos
A1: PROCAFECOL S.A. — ESTADOS FINANCIEROS HISTÓRICOS
A2: Fuente: ISI Markets / Superfinanciera — NIIF | Cifras en Millones COP
A4: Concepto | B4: 2018 | C4: 2019 | D4: 2020 | E4: 2021 | F4: 2022
A5: ESTADO DE RESULTADOS
A6: Ingresos Netos por Ventas | B6: 303132.1 | C6: 338675.61 | D6: 238549.96 | E6: 388699.77 | F6: 594579.87
A7: Costo de Mercancías Vendidas (CMV) | B7: -111064.06 | C7: -131867.39 | D7: -105111.26 | E7: -163909.84 | F7: -255932.16
A8: Utilidad Bruta | B8: 192068.05 | C8: 206808.22 | D8: 133438.71 | E8: 224789.93 | F8: 338647.71
A9: Gastos Operativos (Admin + Venta) | B9: -188364.91 | C9: -196070.11 | D9: -155882.81 | E9: -206041.52 | F9: -286616.31
A10: Gastos Depreciación / Amortización | F10: -31153.9
A11: Otros Resultados Operativos Netos | B11: 5765.44 | C11: 1448.29 | D11: 1575.02 | E11: 5305.57 | F11: 28144.65
A12: EBIT (Ganancia Operativa) | B12: 9468.57 | C12: 14096.42 | D12: -20869.09 | E12: 24053.98 | F12: 49022.16
A13: EBITDA | F13: 80176.05
A14: Gastos Financieros (Intereses) | B14: -7083.92 | C14: -15223.53 | D14: -13361.63 | E14: -10480.55 | F14: -17898.66
A15: Ingresos Financieros | B15: 2205.07 | C15: 171.84 | D15: 386.37 | E15: 4192.97 | F15: 2767.05
A16: Ganancias Antes de Impuestos | B16: 6113.34 | C16: 331.43 | D16: -35165.1 | E16: 20396.5 | F16: 35415.64
A17: Impuesto a la Renta | B17: -2341.49 | C17: -3079.45 | D17: 6251.79 | E17: 1600.27 | F17: -8323.78
A18: UTILIDAD NETA | B18: 3771.85 | C18: -2748.02 | D18: -28913.31 | E18: 21996.77 | F18: 27091.86
A20: BALANCE GENERAL
A21: — ACTIVOS —
A22: Activos Totales | B22: 162079.66 | C22: 229156.19 | D22: 218966.41 | E22: 232419.18 | F22: 316245.81
A23: Activos No Corrientes | B23: 93103.15 | C23: 158446.86 | D23: 137936.12 | E23: 130889.46 | F23: 144642.17
A24: Propiedad, Planta y Equipo | B24: 60904.45 | C24: 127917.18 | D24: 105781.76 | E24: 97682.38 | F24: 63214.48
A25: Activos Intangibles | B25: 7045.56 | C25: 5308 | D25: 4494.17 | E25: 1830.79 | F25: 385.6
A26: Activos Financieros LP | B26: 23209.37 | C26: 23886.96 | D26: 20378.18 | E26: 21415.01 | F26: 18641.67
A27: Otros Activos No Corrientes | B27: 1943.77 | C27: 1334.72 | D27: 7282.01 | E27: 9961.29 | F27: 62400.42
A28: Activos Corrientes | B28: 68976.51 | C28: 70709.33 | D28: 81030.29 | E28: 101529.72 | F28: 171603.63
A29: Inventarios | B29: 24395.32 | C29: 23162.92 | D29: 23093.84 | E29: 41445.24 | F29: 90456.78
A30: Cuentas por Cobrar | B30: 39318.69 | C30: 32875.9 | D30: 24916.27 | E30: 49066.06 | F30: 46115.73
A31: Efectivo y Equivalentes | B31: 4761.42 | C31: 14276.96 | D31: 32900.78 | E31: 9743.56 | F31: 10820.09
A32: Otros Activos Corrientes | B32: 501.08 | C32: 393.56 | D32: 119.41 | E32: 1274.86 | F32: 24210.03
A34: — PASIVOS Y PATRIMONIO —
A35: Pasivos Totales | B35: 130284.13 | C35: 198166.63 | D35: 222529.48 | E35: 224610.04 | F35: 289354.1
A36: Pasivos No Corrientes | B36: 57690.24 | C36: 101472.62 | D36: 118234.65 | E36: 103370.11 | F36: 106875.25
A37: Deuda LP (Créditos y Préstamos NC) | B37: 39039.29 | C37: 78230.64 | D37: 92441.77 | E37: 84265.56 | F37: 36583.01
A38: Otros Pasivos No Corrientes | B38: 18650.96 | C38: 23241.98 | D38: 25792.88 | E38: 19104.55 | F38: 70292.24
A39: Pasivos Corrientes | B39: 72593.89 | C39: 96694.01 | D39: 104294.83 | E39: 121239.93 | F39: 182478.85
A40: Deuda CP (Créditos y Préstamos C) | B40: 28662.1 | C40: 49966.2 | D40: 50705.4 | E40: 51643.92 | F40: 51621.69
A41: Cuentas por Pagar | B41: 34865.56 | C41: 35435.88 | D41: 45832.72 | E41: 55972.96 | F41: 42367.85
A42: Otros Pasivos Corrientes | B42: 9066.23 | C42: 11291.93 | D42: 7756.71 | E42: 13623.05 | F42: 88489.31
A43: Patrimonio Total | B43: 31795.54 | C43: 30989.56 | D43: -3563.07 | E43: 7809.14 | F43: 26891.71
...

Sheet Indicadores
A1: PROCAFECOL S.A. — TABLERO DE INDICADORES FINANCIEROS
A2: Todos los ratios calculados desde datos históricos | Cifras en Millones COP
A4: Indicador | B4: 2018 | C4: 2019 | D4: 2020 | E4: 2021 | F4: 2022 | G4: Referencia / Meta
A5: 1. LIQUIDEZ
A6: Razón Corriente (AC / PC) | B6: ='Datos Históricos'!B28/'Datos Históricos'!B39 -> 0.95016964 | C6: ='Datos Históricos'!C28/'Datos Históricos'!C39 -> 0.73126898 | D6: ='Datos Históricos'!D28/'Datos Históricos'!D39 -> 0.77693487 | E6: ='Datos Históricos'!E28/'Datos Históricos'!E39 -> 0.83742807 | F6: ='Datos Históricos'!F28/'Datos Históricos'!F39 -> 0.94040285 | G6: >1.5x — Cuántos $ de AC por cada $ de PC
A7: Prueba Ácida ((AC - Inv) / PC) | B7: =IFERROR(('Datos Históricos'!B28-'Datos Históricos'!B29)/'Datos Históricos'!B39,"-") -> 0.61411766 | C7: =IFERROR(('Datos Históricos'!C28-'Datos Históricos'!C29)/'Datos Históricos'!C39,"-") -> 0.49172032 | D7: =IFERROR(('Datos Históricos'!D28-'Datos Históricos'!D29)/'Datos Históricos'!D39,"-") -> 0.55550644 | E7: =IFERROR(('Datos Históricos'!E28-'Datos Históricos'!E29)/'Datos Históricos'!E39,"-") -> 0.49558326 | F7: =IFERROR(('Datos Históricos'!F28-'Datos Históricos'!F29)/'Datos Históricos'!F39,"-") -> 0.44469181 | G7: >1.0x — Sin contar inventarios
A8: Razón de Efectivo (Efe / PC) | B8: =IFERROR('Datos Históricos'!B31/'Datos Históricos'!B39,"-") -> 0.065589818 | C8: =IFERROR('Datos Históricos'!C31/'Datos Históricos'!C39,"-") -> 0.14765092 | D8: =IFERROR('Datos Históricos'!D31/'Datos Históricos'!D39,"-") -> 0.31545936 | E8: =IFERROR('Datos Históricos'!E31/'Datos Históricos'!E39,"-") -> 0.080365932 | F8: =IFERROR('Datos Históricos'!F31/'Datos Históricos'!F39,"-") -> 0.059295036 | G8: >0.2x — Lo más conservador
A9: Capital de Trabajo Neto (AC - PC) M COP | B9: =IFERROR('Datos Históricos'!B28-'Datos Históricos'!B39,"-") -> -3617.38 | C9: =IFERROR('Datos Históricos'!C28-'Datos Históricos'!C39,"-") -> -25984.68 | D9: =IFERROR('Datos Históricos'!D28-'Datos Históricos'!D39,"-") -> -23264.54 | E9: =IFERROR('Datos Históricos'!E28-'Datos Históricos'!E39,"-") -> -19710.21 | F9: =IFERROR('Datos Históricos'!F28-'Datos Históricos'!F39,"-") -> -10875.22 | G9: Positivo = puede operar. Negativo = riesgo
A11: 2. ENDEUDAMIENTO
A12: Nivel de Endeudamiento (PT / AT) | B12: =IFERROR('Datos Históricos'!B35/'Datos Históricos'!B22,"-") -> 0.80382776 | C12: =IFERROR('Datos Históricos'!C35/'Datos Históricos'!C22,"-") -> 0.86476665 | D12: =IFERROR('Datos Históricos'!D35/'Datos Históricos'!D22,"-") -> 1.0162722 | E12: =IFERROR('Datos Históricos'!E35/'Datos Históricos'!E22,"-") -> 0.96640062 | F12: =IFERROR('Datos Históricos'!F35/'Datos Históricos'!F22,"-") -> 0.9149658 | G12: <0.60 saludable. >0.80 riesgo alto
A13: Endeudamiento sobre Patrimonio (PT / PAT) | B13: =IFERROR('Datos Históricos'!B35/'Datos Históricos'!B43,"-") -> 4.0975599 | C13: =IFERROR('Datos Históricos'!C35/'Datos Históricos'!C43,"-") -> 6.3946255 | D13: =IFERROR('Datos Históricos'!D35/'Datos Históricos'!D43,"-") -> -62.454423 | E13: =IFERROR('Datos Históricos'!E35/'Datos Históricos'!E43,"-") -> 28.762455 | F13: =IFERROR('Datos Históricos'!F35/'Datos Históricos'!F43,"-") -> 10.759974 | G13: <2.0x recomendado para expansión
A14: Concentración Deuda CP (PC / PT) | B14: =IFERROR('Datos Históricos'!B39/'Datos Históricos'!B35,"-") -> 0.55719672 | C14: =IFERROR('Datos Históricos'!C39/'Datos Históricos'!C35,"-") -> 0.48794295 | D14: =IFERROR('Datos Históricos'!D39/'Datos Históricos'!D35,"-") -> 0.46867871 | E14: =IFERROR('Datos Históricos'!E39/'Datos Históricos'!E35,"-") -> 0.53977966 | F14: =IFERROR('Datos Históricos'!F39/'Datos Históricos'!F35,"-") -> 0.63064201 | G14: <50% indica estructura de deuda sana
A15: Deuda Financiera Total (DCP + DLP) M COP | B15: =IFERROR('Datos Históricos'!B40+'Datos Históricos'!B37,"-") -> 67701.39 | C15: =IFERROR('Datos Históricos'!C40+'Datos Históricos'!C37,"-") -> 128196.84 | D15: =IFERROR('Datos Históricos'!D40+'Datos Históricos'!D37,"-") -> 143147.17 | E15: =IFERROR('Datos Históricos'!E40+'Datos Históricos'!E37,"-") -> 135909.48 | F15: =IFERROR('Datos Históricos'!F40+'Datos Históricos'!F37,"-") -> 88204.7 | G15: Evolución de la deuda con costo
A17: 3. APALANCAMIENTO / COBERTURA
A18: Deuda Neta / EBITDA (solo 2022 con EBITDA) | F18: =IFERROR(('Datos Históricos'!F40+'Datos Históricos'!F37-'Datos Históricos'!F31)/'Datos Históricos'!F13,"-") -> 0.96518362 | G18: <3x para expansión sostenible
A19: Cobertura de Intereses (EBIT / GF) | B19: =IFERROR('Datos Históricos'!B12/-'Datos Históricos'!B14,"-") -> 1.3366286 | C19: =IFERROR('Datos Históricos'!C12/-'Datos Históricos'!C14,"-") -> 0.92596264 | D19: =IFERROR('Datos Históricos'!D12/-'Datos Históricos'!D14,"-") -> -1.5618671 | E19: =IFERROR('Datos Históricos'!E12/-'Datos Históricos'!E14,"-") -> 2.2951066 | F19: =IFERROR('Datos Históricos'!F12/-'Datos Históricos'!F14,"-") -> 2.7388732 | G19: >2.5x ideal. <1.5x es peligroso
A20: Deuda LP / Activos Totales | B20: =IFERROR('Datos Históricos'!B37/'Datos Históricos'!B22,"-") -> 0.24086483 | C20: =IFERROR('Datos Históricos'!C37/'Datos Históricos'!C22,"-") -> 0.34138567 | D20: =IFERROR('Datos Históricos'!D37/'Datos Históricos'!D22,"-") -> 0.42217329 | E20: =IFERROR('Datos Históricos'!E37/'Datos Históricos'!E22,"-") -> 0.36255855 | F20: =IFERROR('Datos Históricos'!F37/'Datos Históricos'!F22,"-") -> 0.11567903 | G20: Muestra qué parte de los activos se financió con deuda LP
A22: 4. EFICIENCIA
A23: Rotación de Activos (Ventas / AT) | B23: =IFERROR('Datos Históricos'!B6/'Datos Históricos'!B22,"-") -> 1.8702661 | C23: =IFERROR('Datos Históricos'!C6/'Datos Históricos'!C22,"-") -> 1.4779248 | D23: =IFERROR('Datos Históricos'!D6/'Datos Históricos'!D22,"-") -> 1.0894363 | E23: =IFERROR('Datos Históricos'!E6/'Datos Históricos'!E22,"-") -> 1.6724083 | F23: =IFERROR('Datos Históricos'!F6/'Datos Históricos'!F22,"-") -> 1.8801194 | G23: >1.0x: genera más de $1 en ventas por cada $1 de activo
A24: Rotación de Inventarios (CMV / Inv) | B24: =IFERROR(-'Datos Históricos'!B7/'Datos Históricos'!B29,"-") -> 4.552679 | C24: =IFERROR(-'Datos Históricos'!C7/'Datos Históricos'!C29,"-") -> 5.6930383 | D24: =IFERROR(-'Datos Históricos'!D7/'Datos Históricos'!D29,"-") -> 4.5514847 | E24: =IFERROR(-'Datos Históricos'!E7/'Datos Históricos'!E29,"-") -> 3.9548532 | F24: =IFERROR(-'Datos Históricos'!F7/'Datos Históricos'!F29,"-") -> 2.8293309 | G24: >6x anual para café (cada ~60 días)
A25: Días de Inventario (365 / RotInv) | B25: =IFERROR(365/(-'Datos Históricos'!B7/'Datos Históricos'!B29),"-") -> 80.172576 | C25: =IFERROR(365/(-'Datos Históricos'!C7/'Datos Históricos'!C29),"-") -> 64.113393 | D25: =IFERROR(365/(-'Datos Históricos'!D7/'Datos Históricos'!D29),"-") -> 80.193612 | E25: =IFERROR(365/(-'Datos Históricos'!E7/'Datos Históricos'!E29),"-") -> 92.291668 | F25: =IFERROR(365/(-'Datos Históricos'!F7/'Datos Históricos'!F29),"-") -> 129.00577 | G25: <60 días ideal para café
A26: Días de Cartera (CxC / Ventas × 365) | B26: =IFERROR('Datos Históricos'!B30/'Datos Históricos'!B6*365,"-") -> 47.343458 | C26: =IFERROR('Datos Históricos'!C30/'Datos Históricos'!C6*365,"-") -> 35.43126 | D26: =IFERROR('Datos Históricos'!D30/'Datos Históricos'!D6*365,"-") -> 38.123832 | E26: =IFERROR('Datos Históricos'!E30/'Datos Históricos'!E6*365,"-") -> 46.074408 | F26: =IFERROR('Datos Históricos'!F30/'Datos Históricos'!F6*365,"-") -> 28.309471 | G26: <45 días. Más alto = tarda más en cobrar
A27: Días de Pago (CxP / CMV × 365) | B27: =IFERROR(-'Datos Históricos'!B41/-'Datos Históricos'!B7*365,"-") -> -114.58189 | C27: =IFERROR(-'Datos Históricos'!C41/-'Datos Históricos'!C7*365,"-") -> -98.084115 | D27: =IFERROR(-'Datos Históricos'!D41/-'Datos Históricos'!D7*365,"-") -> -159.15462 | E27: =IFERROR(-'Datos Históricos'!E41/-'Datos Históricos'!E7*365,"-") -> -124.64249 | F27: =IFERROR(-'Datos Históricos'!F41/-'Datos Históricos'!F7*365,"-") -> -60.423298 | G27: >30 días. Más alto = más tiempo para pagar proveedores
A29: 5. RENTABILIDAD
A30: Margen Bruto (UB / Ventas) | B30: =IFERROR('Datos Históricos'!B8/'Datos Históricos'!B6,"-") -> 0.63361172 | C30: =IFERROR('Datos Históricos'!C8/'Datos Históricos'!C6,"-") -> 0.61063807 | D30: =IFERROR('Datos Históricos'!D8/'Datos Históricos'!D6,"-") -> 0.55937427 | E30: =IFERROR('Datos Históricos'!E8/'Datos Históricos'!E6,"-") -> 0.57831249 | F30: =IFERROR('Datos Históricos'!F8/'Datos Históricos'!F6,"-") -> 0.56955798 | G30: >50% en specialty coffee es bueno
A31: Margen EBIT (EBIT / Ventas) | B31: =IFERROR('Datos Históricos'!B12/'Datos Históricos'!B6,"-") -> 0.031235788 | C31: =IFERROR('Datos Históricos'!C12/'Datos Históricos'!C6,"-") -> 0.041622188 | D31: =IFERROR('Datos Históricos'!D12/'Datos Históricos'!D6,"-") -> -0.0874831 | E31: =IFERROR('Datos Históricos'!E12/'Datos Históricos'!E6,"-") -> 0.061883186 | F31: =IFERROR('Datos Históricos'!F12/'Datos Históricos'!F6,"-") -> 0.082448402 | G31: Meta expansión: >8%. 2022 es base
A32: Margen EBITDA (EBITDA / Ventas — solo 2022) | F32: =IFERROR('Datos Históricos'!F13/'Datos Históricos'!F6,"-") -> 0.13484488 | G32: Meta: >15% a medida que escale internacional
A33: Margen Neto (UN / Ventas) | B33: =IFERROR('Datos Históricos'!B18/'Datos Históricos'!B6,"-") -> 0.012442925 | C33: =IFERROR('Datos Históricos'!C18/'Datos Históricos'!C6,"-") -> -0.008114018 | D33: =IFERROR('Datos Históricos'!D18/'Datos Históricos'!D6,"-") -> -0.12120442 | E33: =IFERROR('Datos Históricos'!E18/'Datos Históricos'!E6,"-") -> 0.056590643 | F33: =IFERROR('Datos Históricos'!F18/'Datos Históricos'!F6,"-") -> 0.045564711 | G33: Meta sostenida: >5%
A34: ROA (UN / Activos Totales) | B34: =IFERROR('Datos Históricos'!B18/'Datos Históricos'!B22,"-") -> 0.023271581 | C34: =IFERROR('Datos Históricos'!C18/'Datos Históricos'!C22,"-") -> -0.011991908 | D34: =IFERROR('Datos Históricos'!D18/'Datos Históricos'!D22,"-") -> -0.1320445 | E34: =IFERROR('Datos Históricos'!E18/'Datos Históricos'!E22,"-") -> 0.094642662 | F34: =IFERROR('Datos Históricos'!F18/'Datos Históricos'!F22,"-") -> 0.085667095 | G34: >5% en expansión es referencia
A35: ROE (UN / Patrimonio Total) | B35: =IFERROR('Datos Históricos'!B18/'Datos Históricos'!B43,"-") -> 0.11862827 | C35: =IFERROR('Datos Históricos'!C18/'Datos Históricos'!C43,"-") -> -0.08867567 | D35: =IFERROR('Datos Históricos'!D18/'Datos Históricos'!D43,"-") -> 8.1147185 | E35: =IFERROR('Datos Históricos'!E18/'Datos Históricos'!E43,"-") -> 2.816798 | F35: =IFERROR('Datos Históricos'!F18/'Datos Históricos'!F43,"-") -> 1.0074428 | G35: >10% para atraer inversión. Ojo: pat. negativo en 2020
A36: Crecimiento Ventas YoY | C36: =IFERROR('Datos Históricos'!C6/'Datos Históricos'!B6-1,"-") -> 0.11725419 | D36: =IFERROR('Datos Históricos'!D6/'Datos Históricos'!C6-1,"-") -> -0.2956388 | E36: =IFERROR('Datos Históricos'!E6/'Datos Históricos'!D6-1,"-") -> 0.6294271 | F36: =IFERROR('Datos Históricos'!F6/'Datos Históricos'!E6-1,"-") -> 0.52966355 | G36: >15% para goal expansión 2030

Sheet Proyección 2023-2030
A1: PROCAFECOL S.A. — PROYECCIÓN FINANCIERA 2023–2030
A2: Cifras en Millones COP | Cambiar los supuestos en columna B o en las celdas azules
A4: SUPUESTOS EDITABLES (cambiar estos valores actualiza toda la proyección)
A5: Crecimiento ventas 2023 (efecto JV Turquía + base) | B5: 0.12
A6: Crecimiento ventas 2024 | B6: 0.15
A7: Crecimiento ventas 2025 (España+EE.UU. activos) | B7: 0.18
A8: Crecimiento ventas 2026 | B8: 0.16
A9: Crecimiento ventas 2027 | B9: 0.14
A10: Crecimiento ventas 2028 | B10: 0.12
A11: Crecimiento ventas 2029 | B11: 0.1
A12: Crecimiento ventas 2030 (meta doble revenue) | B12: 0.11
A13: Margen Bruto (% sobre ventas) | B13: 0.57
A14: Gastos Operativos (% sobre ventas) | B14: 0.42
A15: Gastos Financieros (% sobre ventas) | B15: 0.03
A16: Tasa efectiva de impuestos | B16: 0.3
... A22: Cuentas por Pagar como % de CMV | B22: 0.15
A23: Patrimonio = Activos - Pasivos (calculado) | B23: ↓ calculado
A25: Concepto | B25: 2022 (Base) | C25: 2023 | D25: 2024 | E25: 2025 | F25: 2026 | G25: 2027 | H25: 2028 | I25: 2029 | J25: 2030
A26: ESTADO DE RESULTADOS PROYECTADO
A27: Ingresos Netos por Ventas | B27: ='Datos Históricos'!F6 -> 594579.87 | C27: =B27*(1+$B$5) -> 665929.45 | D27: =C27*(1+$B$6) -> 765818.87 | E27: =D27*(1+$B$7) -> 903666.27 | F27: =E27*(1+$B$8) -> 1048252.9 | G27: =F27*(1+$B$9) -> 1195008.3 | H27: =G27*(1+$B$10) -> 1338409.3 | I27: =H27*(1+$B$11) -> 1472250.2 | J27: =I27*(1+$B$12) -> 1634197.7
A28: Costo de Mercancías Vendidas | B28: ='Datos Históricos'!F7 -> -255932.16 | C28: =-C27*(1-$B$13) -> -286349.67 | D28: =-D27*(1-$B$13) -> -329302.12 | E28: =-E27*(1-$B$13) -> -388576.5 | F28: =-F27*(1-$B$13) -> -450748.74 | G28: =-G27*(1-$B$13) -> -513853.56 | H28: =-H27*(1-$B$13) -> -575515.99 | I28: =-I27*(1-$B$13) -> -633067.58 | J28: =-J27*(1-$B$13) -> -702705.02
A29: Utilidad Bruta | B29: ='Datos Históricos'!F8 -> 338647.71 | C29: =C27+C28 -> 379579.79 | D29: =D27+D28 -> 436516.76 | E29: =E27+E28 -> 515089.77 | F29: =F27+F28 -> 597504.14 | G29: =G27+G28 -> 681154.72 | H29: =H27+H28 -> 762893.28 | I29: =I27+I28 -> 839182.61 | J29: =J27+J28 -> 931492.7
A30: Gastos Operativos | B30: ='Datos Históricos'!F9 -> -286616.31 | C30: =-C27*$B$14 -> -279690.37 | D30: =-D27*$B$14 -> -321643.93 | E30: =-E27*$B$14 -> -379539.83 | F30: =-F27*$B$14 -> -440266.21 | G30: =-G27*$B$14 -> -501903.48 | H30: =-H27*$B$14 -> -562131.89 | I30: =-I27*$B$14 -> -618345.08 | J30: =-J27*$B$14 -> -686363.04
A31: EBIT | B31: ='Datos Históricos'!F12 -> 49022.16 | C31: =C29+C30 -> 99889.418 | D31: =D29+D30 -> 114872.83 | E31: =E29+E30 -> 135549.94 | F31: =F29+F30 -> 157237.93 | G31: =G29+G30 -> 179251.24 | H31: =H29+H30 -> 200761.39 | I31: =I29+I30 -> 220837.53 | J31: =J29+J30 -> 245129.66
A32: Gastos Financieros | B32: ='Datos Históricos'!F14 -> -17898.66 | C32: =-C27*$B$15 -> -19977.884 | D32: =-D27*$B$15 -> -22974.566 | E32: =-E27*$B$15 -> -27109.988 | F32: =-F27*$B$15 -> -31447.586 | G32: =-G27*$B$15 -> -35850.248 | H32: =-H27*$B$15 -> -40152.278 | I32: =-I27*$B$15 -> -44167.506 | J32: =-J27*$B$15 -> -49025.931
A33: EBT (Antes de Impuestos) | C33: =C31+C32 -> 79911.535 | D33: =D31+D32 -> 91898.265 | E33: =E31+E32 -> 108439.95 | F33: =F31+F32 -> 125790.34 | G33: =G31+G32 -> 143400.99 | H33: =H31+H32 -> 160609.11 | I33: =I31+I32 -> 176670.02 | J33: =J31+J32 -> 196103.73
A34: Impuesto (estimado) | C34: =IFERROR(-MAX(0,C33)*$B$16,0) -> -23973.46 | D34: =IFERROR(-MAX(0,D33)*$B$16,0) -> -27569.479 | E34: =IFERROR(-MAX(0,E33)*$B$16,0) -> -32531.986 | F34: =IFERROR(-MAX(0,F33)*$B$16,0) -> -37737.103 | G34: =IFERROR(-MAX(0,G33)*$B$16,0) -> -43020.298 | H34: =IFERROR(-MAX(0,H33)*$B$16,0) -> -48182.734 | I34: =IFERROR(-MAX(0,I33)*$B$16,0) -> -53001.007 | J34: =IFERROR(-MAX(0,J33)*$B$16,0) -> -58831.118
A35: UTILIDAD NETA | B35: ='Datos Históricos'!F18 -> 27091.86 | C35: =C33+C34 -> 55938.074 | D35: =D33+D34 -> 64328.785 | E35: =E33+E34 -> 75907.967 | F35: =F33+F34 -> 88053.241 | G35: =G33+G34 -> 100380.7 | H35: =H33+H34 -> 112426.38 | I35: =I33+I34 -> 123669.02 | J35: =J33+J34 -> 137272.61
A37: BALANCE PROYECTADO | B37: 2022 (Base) | C37: 2023 | D37: 2024 | E37: 2025 | F37: 2026 | G37: 2027 | H37: 2028 | I37: 2029 | J37: 2030
A38: Activos Totales | B38: ='Datos Históricos'!F22 -> 316245.81 | C38: =C27*$B$17 -> 299668.25 | D38: =D27*$B$17 -> 344618.49 | E38: =E27*$B$17 -> 406649.82 | F38: =F27*$B$17 -> 471713.79 | G38: =G27*$B$17 -> 537753.72 | H38: =H27*$B$17 -> 602284.17 | I38: =I27*$B$17 -> 662512.59 | J38: =J27*$B$17 -> 735388.97
A39: Inventarios | B39: ='Datos Históricos'!F29 -> 90456.78 | C39: =-C28*$B$20 -> 91631.893 | D39: =-D28*$B$20 -> 105376.68 | E39: =-E28*$B$20 -> 124344.48 | F39: =-F28*$B$20 -> 144239.6 | G39: =-G28*$B$20 -> 164433.14 | H39: =-H28*$B$20 -> 184165.12 | I39: =-I28*$B$20 -> 202581.63 | J39: =-J28*$B$20 -> 224865.61
A40: Cuentas por Cobrar | B40: ='Datos Históricos'!F30 -> 46115.73 | C40: =C27*$B$21 -> 49944.709 | D40: =D27*$B$21 -> 57436.415 | E40: =E27*$B$21 -> 67774.97 | F40: =F27*$B$21 -> 78618.965 | G40: =G27*$B$21 -> 89625.621 | H40: =H27*$B$21 -> 100380.7 | I40: =I27*$B$21 -> 110418.76 | J40: =J27*$B$21 -> 122564.83
A41: Efectivo | B41: ='Datos Históricos'!F31 -> 10820.09 | C41: =C27*$B$19 -> 23307.531 | D41: =D27*$B$19 -> 26803.661 | E41: =E27*$B$19 -> 31628.319 | F41: =F27*$B$19 -> 36688.851 | G41: =G27*$B$19 -> 41825.29 | H41: =H27*$B$19 -> 46844.324 | I41: =I27*$B$19 -> 51528.757 | J41: =J27*$B$19 -> 57196.92
A42: Deuda Financiera Total | B42: ='Datos Históricos'!F40+'Datos Históricos'!F37 -> 88204.7 | C42: =C38*$B$18 -> 83907.111 | D42: =D38*$B$18 -> 96493.178 | E42: =E38*$B$18 -> 113861.95 | F42: =F38*$B$18 -> 132079.86 | G42: =G38*$B$18 -> 150571.04 | H42: =H38*$B$18 -> 168639.57 | I42: =I38*$B$18 -> 185503.52 | J42: =J38*$B$18 -> 205908.91
A43: Cuentas por Pagar | B43: ='Datos Históricos'!F41 -> 42367.85 | C43: =-C28*$B$22 -> 42952.45 | D43: =-D28*$B$22 -> 49395.317 | E43: =-E28*$B$22 -> 58286.474 | F43: =-F28*$B$22 -> 67612.31 | G43: =-G28*$B$22 -> 77078.034 | H43: =-H28*$B$22 -> 86327.398 | I43: =-I28*$B$22 -> 94960.138 | J43: =-J28*$B$22 -> 105405.75
A44: Patrimonio Estimado (AT - Pasivos) | B44: ='Datos Históricos'!F43 -> 26891.71 | C44: =C38-C42*2 -> 131854.03 | D44: =D38-D42*2 -> 151632.14 | E44: =E38-E42*2 -> 178925.92 | F44: =F38-F42*2 -> 207554.07 | G44: =G38-G42*2 -> 236611.64 | H44: =H38-H42*2 -> 265005.04 | I44: =I38-I42*2 -> 291505.54 | J44: =J38-J42*2 -> 323571.15
A46: INDICADORES PROYECTADOS | B46: 2022 (Base) | C46: 2023 | D46: 2024 | E46: 2025 | F46: 2026 | G46: 2027 | H46: 2028 | I46: 2029 | J46: 2030
A47: Crecimiento Ventas YoY | C47: =$B$5 -> 0.12 | D47: =$B$6 -> 0.15 | E47: =$B$7 -> 0.18 | F47: =$B$8 -> 0.16 | G47: =$B$9 -> 0.14 | H47: =$B$10 -> 0.12 | I47: =$B$11 -> 0.1 | J47: =$B$12 -> 0.11
A48: Margen Bruto | B48: =Indicadores!F30 -> 0.56955798 | C48: =$B$13 -> 0.57 | D48: =$B$13 -> 0.57 | E48: =$B$13 -> 0.57 | F48: =$B$13 -> 0.57 | G48: =$B$13 -> 0.57 | H48: =$B$13 -> 0.57 | I48: =$B$13 -> 0.57 | J48: =$B$13 -> 0.57
A49: Margen EBIT | B49: =Indicadores!F31 -> 0.082448402 | C49: =IFERROR(C31/C27,"-") -> 0.15 | D49: =IFERROR(D31/D27,"-") -> 0.15 | E49: =IFERROR(E31/E27,"-") -> 0.15 | F49: =IFERROR(F31/F27,"-") -> 0.15 | G49: =IFERROR(G31/G27,"-") -> 0.15 | H49: =IFERROR(H31/H27,"-") -> 0.15 | I49: =IFERROR(I31/I27,"-") -> 0.15 | J49: =IFERROR(J31/J27,"-") -> 0.15
...

Sheet Glosario
A1: GLOSARIO DE INDICADORES — GUÍA DE LECTURA
A2: Indicador | B2: ¿Qué mide? | C2: Fórmula | D2: Señal de Alerta
A3: Razón Corriente | B3: ¿Puede pagar deudas corto plazo con activos cortos? | C3: AC / PC | D3: >1.5x. <1.0x = riesgo de iliquidez
A4: Prueba Ácida | B4: ¿Qué tánta liquidez depende de los inventarios (activo menos líquido)? | C4: (AC - Inv) / PC | D4: >1.0x ideal
A5: Razón de Efectivo | B5: ¿Con solo el efectivo puede cubrir pasivos corrientes? | C5: Efectivo / PC | D5: >0.2x mínimo
A6: Capital de Trabajo | B6: Margen de seguridad operativo en pesos | C6: AC - PC | D6: Positivo siempre. Negativo = problema
A7: Nivel Endeudamiento | B7: % de los activos financiado con deuda | C7: Pasivos / Activos | D7: <60%. >80% = muy apalancada
A8: Deuda/Patrimonio (D/E) | B8: Cuántos pesos de deuda por cada peso propio | C8: Pasivos / Patrimonio | D8: <2.0x para expansión
A9: Concentración Deuda CP | B9: ¿Qué % de la deuda vence en menos de 1 año? | C9: PC / Pasivos Totales | D9: <50% saludable
A10: Deuda Neta/EBITDA | B10: Años que tomaría pagar la deuda con el EBITDA | C10: (Deuda - Efe) / EBITDA | D10: <3x para expansión internacional
A11: Cobertura de Intereses | B11: ¿Cuántas veces cubre el EBIT los intereses? | C11: EBIT / Gastos Financieros | D11: >2.5x ideal. <1.5x peligroso
A12: Rotación de Activos | B12: ¿Cuántas veces vende por cada peso en activos? | C12: Ventas / Activos Totales | D12: >1.0x deseado
A13: Días de Inventario | B13: ¿Cuántos días tarda en vender el inventario? | C13: 365 / Rotación Inventarios | D13: <60 días para café
... A22: Crecimiento Ventas YoY | B22: Variación porcentual de ventas vs. año anterior | C22: (Ventas t / Ventas t-1) - 1 | D22: >15% para meta doble revenue 2030
